Workbook

Sheet Cover
B2: MAGE ID
B3: Construction Operating System for the Modern GC
B5: Three-Year Business Projection & Strategic Plan
B6: May 2026 — April 2029
B8: Prepared: May 6, 2026
B9: Built by a 25-year general contractor with input from 100+ contractors
B11: How to use this model
B12: 1. | C12: Open the Assumptions tab. Cells in BLUE are the only inputs you should change.
B13: 2. | C13: Yellow-highlighted cells are the most leverage-bearing assumptions. Change those first to see scenario effects.
B14: 3. | C14: Every other tab pulls from Assumptions via formulas. Outputs update automatically.
B15: 4. | C15: Realistic / Conservative / Optimistic tabs show three pre-built scenarios.
B16: 5. | C16: Y1 Monthly tab is the granular conversion ramp underlying Y1 numbers.
B17: 6. | C17: KPIs tab is what you should be tracking weekly to know which scenario you're tracking toward.
B20: Bottom-line summary across scenarios
B22: Metric | C22: Conservative | D22: Realistic | E22: Optimistic
B23: Y1 paying users (EOY) | C23: =Conservative!C13 | D23: =Realistic!C13 | E23: =Optimistic!C13
B24: Y1 ARR | C24: =Conservative!C24 | D24: =Realistic!C24 | E24: =Optimistic!C24
B25: Y2 paying users (EOY) | C25: =Conservative!D13 | D25: =Realistic!D13 | E25: =Optimistic!D13
B26: Y2 ARR | C26: =Conservative!D24 | D26: =Realistic!D24 | E26: =Optimistic!D24
B27: Y3 paying users (EOY) | C27: =Conservative!E13 | D27: =Realistic!E13 | E27: =Optimistic!E13
B28: Y3 ARR | C28: =Conservative!E24 | D28: =Realistic!E24 | E28: =Optimistic!E24
B29: Y3 net margin | C29: =Conservative!E22 | D29: =Realistic!E22 | E29: =Optimistic!E22
B30: Y3 net takehome | C30: =Conservative!E21 | D30: =Realistic!E21 | E30: =Optimistic!E21
B31: 3-yr cumulative net | C31: =Conservative!F21 | D31: =Realistic!F21 | E31: =Optimistic!F21

Sheet Assumptions
B2: INPUT ASSUMPTIONS
B3: Edit BLUE cells only. Yellow-highlighted = highest leverage.
B4: Every other sheet pulls from here via formulas.
B6: PRICING (monthly subscription)
B7: Pro tier $/mo | C7: 29 | D7: Apple price tier 29
B8: Business tier $/mo | C8: 79 | D8: Apple price tier 79
B9: Enterprise tier $/mo | C9: 149.99 | D9: Apple price tier 150 = $149.99
B11: TIER MIX (% of paying users)
B12: % Pro | C12: 0.65 | D12: Industry benchmark for SMB SaaS lower tier
B13: % Business | C13: 0.25
B14: % Enterprise | C14: 0.1 | D14: Heavy AI users / multi-team firms
B15: Sum check | C15: =C12+C13+C14
B17: FUNNEL & RETENTION
B18: Free → paid conversion % | C18: 0.085 | D18: Industry SMB SaaS: 5-12%
B19: Monthly logo churn | C19: 0.05 | D19: 5%/mo realistic / 3%/mo opt / 7%/mo cons
B20: Annual subscription mix | C20: 0.3 | D20: % of subs that buy annual
B21: Blended annual discount % | C21: 0.197 | D21: 0.65×17% + 0.25×17% + 0.10×44.4% (Enterprise capped at $999.99)
B23: COST PER PAYING USER ($/mo)
B24: Gemini AI — Pro typical | C24: 3.5 | D24: 30% of cap usage
B25: Gemini AI — Business typical | C25: 10
B26: Gemini AI — Enterprise typical | C26: 22
B27: Supabase + RC + email + push (blended) | C27: 0.8
B29: APP STORE FEES
B30: Y1 store-fee blended | C30: 0.3 | D30: Apple/Google take 30% on first-year subs
B31: Y2 store-fee blended | C31: 0.22 | D31: Mix of new (30%) + renewing (15%)
B32: Y3 store-fee blended | C32: 0.18 | D32: Mostly renewing
B34: MARKETING SPEND ($)
B35: Y1 marketing budget | C35: 30000 | D35: SEO + content + tools
B36: Y2 marketing budget | C36: 130000 | D36: Paid + trade show
B37: Y3 marketing budget | C37: 330000 | D37: Full team + paid + trade
B39: FOUNDER + TEAM ($/yr)
B40: Y1 founder salary | C40: 60000 | D40: Survival mode
B41: Y2 founder salary | C41: 120000 | D41: Real salary
B42: Y3 founder salary | C42: 180000 | D42: Market rate
B43: Y2 part-time hire | C43: 48000 | D43: Content / community ($4K/mo)
B44: Y3 full-time hires (2) | C44: 220000 | D44: Support + sales/content
B46: OTHER
B47: Y1 tools spend | C47: 3600 | D47: $300/mo
B48: Y2 tools spend | C48: 8400
B49: Y3 tools spend | C49: 15000
...

Sheet Conservative
B2: Conservative Scenario — 3-Year P&L
B3: All values pull from Assumptions tab. Black = formula, Green = cross-sheet link.
B5: Line item | C5: Y1 | D5: Y2 | E5: Y3 | F5: 3-Yr Total
B7: USER METRICS
B8: Avg paying users (year) | C8: =Assumptions!C56*Assumptions!C61 | D8: =Assumptions!D56*Assumptions!C62 | E8: =Assumptions!E56*Assumptions!C63
B9: Paying users (EOY) | C9: =Assumptions!C56 | D9: =Assumptions!D56 | E9: =Assumptions!E56
B10: Effective ARPU / mo | C10: =Assumptions!C67 | D10: =Assumptions!C67 | E10: =Assumptions!C67
B11: GROSS REVENUE | C11: =C8*C10*12 | D11: =D8*D10*12 | E11: =E8*E10*12 | F11: =SUM(C11:E11)
B13: Paying users at EOY | C13: =Assumptions!C56 | D13: =Assumptions!D56 | E13: =Assumptions!E56
B15: COSTS
B16: App store fees | C16: =C11*Assumptions!C30*-1 | D16: =D11*Assumptions!C31*-1 | E16: =E11*Assumptions!C32*-1
B17: Variable costs (AI, Supabase, RC, email) | C17: =-C8*Assumptions!C70*12 | D17: =-D8*Assumptions!C70*12 | E17: =-E8*Assumptions!C70*12
B18: Marketing spend | C18: =-Assumptions!C35 | D18: =-Assumptions!C36 | E18: =-Assumptions!C37
B19: Tools (Sentry, PostHog, etc) | C19: =-Assumptions!C47 | D19: =-Assumptions!C48 | E19: =-Assumptions!C49
B20: Founder + team salaries | C20: =-Assumptions!C40 | D20: =-Assumptions!C41-Assumptions!C43 | E20: =-Assumptions!C42-Assumptions!C44
B21: NET INCOME | C21: =C11+C16+C17+C18+C19+C20 | D21: =D11+D16+D17+D18+D19+D20+Assumptions!C50 | E21: =E11+E16+E17+E18+E19+E20+Assumptions!C51 | F21: =SUM(C21:E21)
B22: Net margin % | C22: =IFERROR(C21/C11,0) | D22: =IFERROR(D21/D11,0) | E22: =IFERROR(E21/E11,0)
B24: ENDING ARR (run-rate) | C24: =C13*C10*12 | D24: =D13*D10*12 | E24: =E13*E10*12

Sheet Realistic
B2: Realistic Scenario — 3-Year P&L
B3: All values pull from Assumptions tab. Black = formula, Green = cross-sheet link.
B5: Line item | C5: Y1 | D5: Y2 | E5: Y3 | F5: 3-Yr Total
B7: USER METRICS
B8: Avg paying users (year) | C8: =Assumptions!C57*Assumptions!C61 | D8: =Assumptions!D57*Assumptions!C62 | E8: =Assumptions!E57*Assumptions!C63
B9: Paying users (EOY) | C9: =Assumptions!C57 | D9: =Assumptions!D57 | E9: =Assumptions!E57
B10: Effective ARPU / mo | C10: =Assumptions!C67 | D10: =Assumptions!C67 | E10: =Assumptions!C67
B11: GROSS REVENUE | C11: =C8*C10*12 | D11: =D8*D10*12 | E11: =E8*E10*12 | F11: =SUM(C11:E11)
B13: Paying users at EOY | C13: =Assumptions!C57 | D13: =Assumptions!D57 | E13: =Assumptions!E57
B15: COSTS
B16: App store fees | C16: =C11*Assumptions!C30*-1 | D16: =D11*Assumptions!C31*-1 | E16: =E11*Assumptions!C32*-1
B17: Variable costs (AI, Supabase, RC, email) | C17: =-C8*Assumptions!C70*12 | D17: =-D8*Assumptions!C70*12 | E17: =-E8*Assumptions!C70*12
B18: Marketing spend | C18: =-Assumptions!C35 | D18: =-Assumptions!C36 | E18: =-Assumptions!C37
B19: Tools (Sentry, PostHog, etc) | C19: =-Assumptions!C47 | D19: =-Assumptions!C48 | E19: =-Assumptions!C49
B20: Founder + team salaries | C20: =-Assumptions!C40 | D20: =-Assumptions!C41-Assumptions!C43 | E20: =-Assumptions!C42-Assumptions!C44
B21: NET INCOME | C21: =C11+C16+C17+C18+C19+C20 | D21: =D11+D16+D17+D18+D19+D20+Assumptions!C50 | E21: =E11+E16+E17+E18+E19+E20+Assumptions!C51 | F21: =SUM(C21:E21)
B22: Net margin % | C22: =IFERROR(C21/C11,0) | D22: =IFERROR(D21/D11,0) | E22: =IFERROR(E21/E11,0)
B24: ENDING ARR (run-rate) | C24: =C13*C10*12 | D24: =D13*D10*12 | E24: =E13*E10*12

Sheet Optimistic
B2: Optimistic Scenario — 3-Year P&L
B3: All values pull from Assumptions tab. Black = formula, Green = cross-sheet link.
B5: Line item | C5: Y1 | D5: Y2 | E5: Y3 | F5: 3-Yr Total
B7: USER METRICS
B8: Avg paying users (year) | C8: =Assumptions!C58*Assumptions!C61 | D8: =Assumptions!D58*Assumptions!C62 | E8: =Assumptions!E58*Assumptions!C63
B9: Paying users (EOY) | C9: =Assumptions!C58 | D9: =Assumptions!D58 | E9: =Assumptions!E58
B10: Effective ARPU / mo | C10: =Assumptions!C67 | D10: =Assumptions!C67 | E10: =Assumptions!C67
B11: GROSS REVENUE | C11: =C8*C10*12 | D11: =D8*D10*12 | E11: =E8*E10*12 | F11: =SUM(C11:E11)
B13: Paying users at EOY | C13: =Assumptions!C58 | D13: =Assumptions!D58 | E13: =Assumptions!E58
B15: COSTS
B16: App store fees | C16: =C11*Assumptions!C30*-1 | D16: =D11*Assumptions!C31*-1 | E16: =E11*Assumptions!C32*-1
B17: Variable costs (AI, Supabase, RC, email) | C17: =-C8*Assumptions!C70*12 | D17: =-D8*Assumptions!C70*12 | E17: =-E8*Assumptions!C70*12
B18: Marketing spend | C18: =-Assumptions!C35 | D18: =-Assumptions!C36 | E18: =-Assumptions!C37
B19: Tools (Sentry, PostHog, etc) | C19: =-Assumptions!C47 | D19: =-Assumptions!C48 | E19: =-Assumptions!C49
B20: Founder + team salaries | C20: =-Assumptions!C40 | D20: =-Assumptions!C41-Assumptions!C43 | E20: =-Assumptions!C42-Assumptions!C44
B21: NET INCOME | C21: =C11+C16+C17+C18+C19+C20 | D21: =D11+D16+D17+D18+D19+D20+Assumptions!C50 | E21: =E11+E16+E17+E18+E19+E20+Assumptions!C51 | F21: =SUM(C21:E21)
B22: Net margin % | C22: =IFERROR(C21/C11,0) | D22: =IFERROR(D21/D11,0) | E22: =IFERROR(E21/E11,0)
B24: ENDING ARR (run-rate) | C24: =C13*C10*12 | D24: =D13*D10*12 | E24: =E13*E10*12

Sheet Y1 Monthly
B2: Y1 Monthly Conversion Ramp — Realistic Scenario
B3: Free signups & conversions are hardcoded ramp inputs. Cumulative paid applies the monthly churn from Assumptions!C19.
B5: Month | C5: Free signups | D5: Paid conversions | E5: Churn this month | F5: Net new paid | G5: Cumulative paid (EOM)
B6: 1 | C6: 50 | D6: 5 | E6: =0 | F6: =D6+E6 | G6: =D6
B7: 2 | C7: 100 | D7: 15 | E7: =ROUND(G6*Assumptions!C19,0)*-1 | F7: =D7+E7 | G7: =G6+D7+E7
B8: 3 | C8: 200 | D8: 25 | E8: =ROUND(G7*Assumptions!C19,0)*-1 | F8: =D8+E8 | G8: =G7+D8+E8
B9: 4 | C9: 300 | D9: 40 | E9: =ROUND(G8*Assumptions!C19,0)*-1 | F9: =D9+E9 | G9: =G8+D9+E9
B10: 5 | C10: 400 | D10: 50 | E10: =ROUND(G9*Assumptions!C19,0)*-1 | F10: =D10+E10 | G10: =G9+D10+E10
B11: 6 | C11: 500 | D11: 60 | E11: =ROUND(G10*Assumptions!C19,0)*-1 | F11: =D11+E11 | G11: =G10+D11+E11
B12: 7 | C12: 600 | D12: 70 | E12: =ROUND(G11*Assumptions!C19,0)*-1 | F12: =D12+E12 | G12: =G11+D12+E12
B13: 8 | C13: 700 | D13: 75 | E13: =ROUND(G12*Assumptions!C19,0)*-1 | F13: =D13+E13 | G13: =G12+D13+E13
B14: 9 | C14: 800 | D14: 80 | E14: =ROUND(G13*Assumptions!C19,0)*-1 | F14: =D14+E14 | G14: =G13+D14+E14
B15: 10 | C15: 900 | D15: 85 | E15: =ROUND(G14*Assumptions!C19,0)*-1 | F15: =D15+E15 | G15: =G14+D15+E15
B16: 11 | C16: 1000 | D16: 90 | E16: =ROUND(G15*Assumptions!C19,0)*-1 | F16: =D16+E16 | G16: =G15+D16+E16
B17: 12 | C17: 1100 | D17: 95 | E17: =ROUND(G16*Assumptions!C19,0)*-1 | F17: =D17+E17 | G17: =G16+D17+E17
B18: TOTAL | C18: =SUM(C6:C17) | D18: =SUM(D6:D17) | E18: =SUM(E6:E17) | F18: =SUM(F6:F17) | G18: =G17

Sheet Unit Economics
B2: Unit Economics
B3: Per-user cost, gross margin, LTV, CAC budget. Pulls Pricing + costs from Assumptions.
B5: Cost / margin per user | C5: Pro | D5: Business | E5: Enterprise | F5: Blended
B6: Subscription $/mo | C6: =Assumptions!C7 | D6: =Assumptions!C8 | E6: =Assumptions!C9 | F6: =Assumptions!C66
B7: Variable cost $/mo (AI + infra) | C7: =Assumptions!C24+Assumptions!C27 | D7: =Assumptions!C25+Assumptions!C27 | E7: =Assumptions!C26+Assumptions!C27 | F7: =Assumptions!C70
B8: App store fee $/mo (Y2+ 15%) | C8: =C6*0.15 | D8: =D6*0.15 | E8: =E6*0.15 | F8: =F6*0.15
B9: Gross margin $/mo (Y2+) | C9: =C6-C7-C8 | D9: =D6-D7-D8 | E9: =E6-E7-E8 | F9: =F6-F7-F8
B10: Gross margin % | C10: =C9/C6 | D10: =D9/D6 | E10: =E9/E6 | F10: =F9/F6
B12: LTV : CAC
B13: Avg lifetime (months) | C13: =1/Assumptions!C19
B14: LTV (gross margin × lifetime) | C14: =F9*C13
B15: Target CAC (LTV ÷ 3) | C15: =C14/3
B16: Acceptable CAC ceiling (LTV ÷ 2) | C16: =C14/2
B18: Channel CAC reference (industry benchmarks)
B19: Channel | C19: CAC range | D19: Y1 priority
B20: Word-of-mouth (referral) | C20: $0 | D20: Build for it
B21: Long-form YouTube | C21: $40-80 | D21: Start week 1
B22: TikTok / Instagram Reels | C22: $30-60 | D22: Start week 1
B23: SEO long-tail content | C23: $50-100 | D23: Start week 2
B24: Reddit / forum presence | C24: $20-40 | D24: Daily
B25: Cold email to scraped GCs | C25: $80-150 | D25: M3+
B26: Google Ads (competitor names) | C26: $200-400 | D26: M6+
B27: Meta ads (lookalikes) | C27: $300-500 | D27: M9+
B28: Trade shows | C28: $500-1,000 | D28: Y2 booth
B29: Houzz Pro / Angi directory | C29: $300-600 | D29: Y2
B30: LinkedIn outbound DMs | C30: Time-cost | D30: Daily 30 min

Sheet KPIs
B2: KPIs to Track Weekly
B3: Targets pull from Assumptions tab. Track these instead of waiting for ARR to reveal trajectory.
B5: Metric | C5: Target | D5: Trigger ↓ (cons) | E5: OK (real) | F5: Trigger ↑ (opt)
B6: ACQUISITION
B7: Free signups / week | C7: 50 | D7: 20 | E7: 50 | F7: 100
B8: Paid conversions / week | C8: 6 | D8: 2 | E8: 6 | F8: 15
B9: Free → paid conversion rate (30d cohort) | C9: =Assumptions!C18 | D9: 0.04 | E9: 0.085 | F9: 0.12
B10: Blended CAC (paid channels) | C10: 240 | D10: 400 | E10: 240 | F10: 150
B11: RETENTION
B12: Monthly logo churn | C12: =Assumptions!C19 | D12: 0.07 | E12: 0.05 | F12: 0.03
B13: Days to first AI estimate | C13: 7 | D13: 14 | E13: 7 | F13: 3
B14: DAU / WAU ratio | C14: 0.4 | D14: 0.2 | E14: 0.4 | F14: 0.6
B15: EXPANSION
B16: Pro → Business upgrade rate / mo | C16: 0.04 | D16: 0.015 | E16: 0.04 | F16: 0.06
B17: Business → Enterprise upgrade / mo | C17: 0.015 | D17: 0.005 | E17: 0.015 | F17: 0.025
B18: Net Revenue Retention | C18: 1 | D18: 0.85 | E18: 1 | F18: 1.1
B19: MONEY
B20: MRR ($) | C20: =Realistic!C13*Realistic!C10 | D20: 8000 | E20: 25000 | F20: 60000
B21: ARR ($) | C21: =Realistic!C24 | D21: 130000 | E21: 340000 | F21: 810000
B22: Months of runway | C22: 12+ | D22: 3 | E22: 12 | F22: 24

Sheet Notes
B2: Model Notes & Sources
B4: APPLE PRICING CAP — IMPORTANT
B5: Apple's standard subscription pricing tiers cap at $999.99 per period. The original plan called for Enterprise Annual at $1,499.99/yr (17% off vs $150 monthly × 12), but that tier is not available in App Store Connect without applying for custom pricing tiers (a multi-week process with Apple support). Enterprise Annual was therefore set to $999.99/yr — the highest standard tier — which equates to $83.33/mo effective (44% off vs $149.99 × 12 = $1,799.88). This is a stronger annual discount than originally planned. Net financial impact on this projection: ~3% lower revenue across all years vs the original plan. The blended annual discount in cell C21 (19.7%) captures this — it's a weighted average of 17% (Pro/Business) and 44.4% (Enterprise capped). Update C21 if Apple later approves a custom $1,499.99 Enterprise tier — the model will re-flow.
B7: Methodology
B8: Numbers use industry benchmarks for residential-construction SaaS (conversion 5-12%, monthly churn 4-7%, CAC ranges per channel) combined with MAGE's actual cost structure verified during the May 2026 pre-launch audit. Cost cap math (Pro 61%, Business 58%, Enterprise 53% gross margin floor) confirmed via curl tests of deployed edge functions and checked against MONTHLY_CAPS in supabase/functions/_shared/auth.ts.
B10: Tier mix rationale
B11: 65% Pro / 25% Business / 10% Enterprise reflects how SMB SaaS lower tiers dominate by user count. Higher tiers carry disproportionate revenue (Enterprise = 10% of users but 27% of revenue at this mix). Adjust mix in Assumptions!C12-C14 to test alternate distributions.
B13: Churn rate source
B14: 5%/mo monthly logo churn is the median for SMB construction SaaS per public data (BuildBook, CompanyCam reports). Realistic scenario uses 5%; Conservative uses 7%; Optimistic uses 3%.
B16: App Store fee blend
B17: Y1: 30% (all subs are first-year). Y2: 22% blended (mix of new 30% + renewing 15%). Y3: 18% blended (mostly renewing). Web subs via RevenueCat web SDK incur no store fee — current model assumes ~10% of subs use web (conservative; could be higher).
B19: Marketing spend rationale
... B29: The two highest-leverage inputs are: (1) Free → paid conversion rate (Assumptions!C18), and (2) Monthly churn (Assumptions!C19). A 1pp swing in either changes Y3 ARR by ~$300-500K. Try setting churn to 3% and conversion to 12% to see optimistic-equivalent outcomes.
